<?xml version="1.0"?>
<sdf version='1.6'>
  <world name="demo">
    <physics name="1ms" type="ignored">
      <max_step_size>0.001</max_step_size>
      <real_time_factor>1.0</real_time_factor>
    </physics>
    <plugin
      filename="ignition-gazebo-physics-system"
      name="ignition::gazebo::systems::Physics">
    </plugin>
    <plugin
      filename="ignition-gazebo-user-commands-system"
      name="ignition::gazebo::systems::UserCommands">
    </plugin>
    <plugin
      filename="ignition-gazebo-scene-broadcaster-system"
      name="ignition::gazebo::systems::SceneBroadcaster">
    </plugin>

    <light type="directional" name="sun">
      <cast_shadows>true</cast_shadows>
      <pose>0 0 10 0 0 0</pose>
      <diffuse>1 1 1 1</diffuse>
      <specular>0.5 0.5 0.5 1</specular>
      <attenuation>
        <range>1000</range>
        <constant>0.9</constant>
        <linear>0.01</linear>
        <quadratic>0.001</quadratic>
      </attenuation>
      <direction>-0.5 0.1 -0.9</direction>
    </light>

    <model name="ground_plane">
      <static>true</static>
      <link name="link">
        <collision name="collision">
          <geometry>
            <plane>
              <normal>0 0 1</normal>
              <size>100 100</size>
            </plane>
          </geometry>
        </collision>
        <visual name="visual">
          <geometry>
            <plane>
              <normal>0 0 1</normal>
              <size>100 100</size>
            </plane>
          </geometry>
          <material>
            <ambient>0.8 0.8 0.8 1</ambient>
            <diffuse>0.8 0.8 0.8 1</diffuse>
            <specular>0.8 0.8 0.8 1</specular>
          </material>
        </visual>
      </link>
    </model>

    <model name='forklift_robot'>
      <link name='base_link'>
        <inertial>
          <pose>0 0 0.1 0 0 0</pose>
          <mass>100</mass>
          <inertia>
            <ixx>10.4</ixx>
            <ixy>0</ixy>
            <ixz>0</ixz>
            <iyy>35.399999999999999</iyy>
            <iyz>0</iyz>
            <izz>41.659999999999997</izz>
          </inertia>
        </inertial>
        <collision name='base_link_fixed_joint_lump__chassis_collision'>
          <pose>0 0 0.1 0 0 0</pose>
          <geometry>
            <box>
              <size>2.159 1.0668 2.7432</size>
            </box>
          </geometry>
        </collision>
        <visual name='base_link_fixed_joint_lump__chassis_visual'>
          <pose>-1.0795 -0.5334 0.1 0 0 0</pose>
          <geometry>
            <mesh>
              <scale>1 1 1</scale>
              <uri>file:///home/ahmad/ros2_ign_diffdrive/src/ros2_ign_p2p_controllers/model/base_link.dae</uri>
            </mesh>
          </geometry>
          <material>
            <diffuse>0 0.625 0.625 1</diffuse>
            <ambient>0 0.625 0.625 1</ambient>
          </material>
        </visual>
      </link>
      <joint name='fork_joint' type='prismatic'>
        <pose relative_to='base_link'>1.0795 0 0.11 0 0 0</pose>
        <parent>base_link</parent>
        <child>fork</child>
        <axis>
          <xyz>0 0 1</xyz>
          <limit>
            <lower>0</lower>
            <upper>2</upper>
            <effort>100</effort>
            <velocity>0.10000000000000001</velocity>
          </limit>
          <dynamics>
            <damping>0.20000000000000001</damping>
            <friction>0</friction>
            <spring_reference>0</spring_reference>
            <spring_stiffness>0</spring_stiffness>
          </dynamics>
        </axis>
      </joint>
      <link name='fork'>
        <pose relative_to='fork_joint'>0 0 0 0 0 0</pose>
        <inertial>
          <pose>0 0 0 0 0 0</pose>
          <mass>100</mass>
          <inertia>
            <ixx>0.20000000000000001</ixx>
            <ixy>0</ixy>
            <ixz>0</ixz>
            <iyy>0.29999999999999999</iyy>
            <iyz>0</iyz>
            <izz>0.40000000000000002</izz>
          </inertia>
        </inertial>
        <collision name='fork_collision'>
          <pose>0 -0.3686 0 0 0 0</pose>
          <geometry>
            <mesh>
              <scale>1 1 1</scale>
              <uri>file:///home/ahmad/ros2_ign_diffdrive/src/ros2_ign_p2p_controllers/model/fork.dae</uri>
            </mesh>
          </geometry>
        </collision>
        <visual name='fork_visual'>
          <pose>0 -0.3686 0 0 0 0</pose>
          <geometry>
            <mesh>
              <scale>1 1 1</scale>
              <uri>file:///home/ahmad/ros2_ign_diffdrive/src/ros2_ign_p2p_controllers/model/fork.dae</uri>
            </mesh>
          </geometry>
          <material>
            <diffuse>1 1 1 1</diffuse>
            <ambient>1 1 1 1</ambient>
          </material>
        </visual>
      </link>
      <joint name='left_wheel_steering_joint' type='revolute'>
        <pose relative_to='base_link'>0.65 -0.3835 0.2 1.57 0 0</pose>
        <parent>base_link</parent>
        <child>left_wheel_steering</child>
        <axis>
          <xyz>0 1 0</xyz>
          <limit>
            <lower>-1.5700000000000001</lower>
            <upper>1.5700000000000001</upper>
            <effort>1000</effort>
            <velocity>30</velocity>
          </limit>
          <dynamics>
            <damping>0.20000000000000001</damping>
            <friction>0</friction>
            <spring_reference>0</spring_reference>
            <spring_stiffness>0</spring_stiffness>
          </dynamics>
        </axis>
      </joint>
      <link name='left_wheel_steering'>
        <pose relative_to='left_wheel_steering_joint'>0 0 0 0 0 0</pose>
        <inertial>
          <pose>0 0 0 0 0 0</pose>
          <mass>0.10000000000000001</mass>
          <inertia>
            <ixx>0</ixx>
            <ixy>0</ixy>
            <ixz>0</ixz>
            <iyy>0</iyy>
            <iyz>0</iyz>
            <izz>0</izz>
          </inertia>
        </inertial>
      </link>
      <joint name='front_left_wheel_joint' type='revolute'>
        <pose relative_to='left_wheel_steering'>0 0 0 0 0 0</pose>
        <parent>left_wheel_steering</parent>
        <child>front_left_wheel</child>
        <axis>
          <xyz>0 0 1</xyz>
          <limit>
            <lower>-10000000000000000</lower>
            <upper>10000000000000000</upper>
          </limit>
          <dynamics>
            <damping>0.20000000000000001</damping>
            <friction>0</friction>
            <spring_reference>0</spring_reference>
            <spring_stiffness>0</spring_stiffness>
          </dynamics>
        </axis>
      </joint>
      <link name='front_left_wheel'>
        <pose relative_to='front_left_wheel_joint'>0 0 0 0 0 0</pose>
        <inertial>
          <pose>0 0 0 0 0 0</pose>
          <mass>11.300000000000001</mass>
          <inertia>
            <ixx>0.26000000000000001</ixx>
            <ixy>0</ixy>
            <ixz>0</ixz>
            <iyy>0.26000000000000001</iyy>
            <iyz>0</iyz>
            <izz>0.51000000000000001</izz>
          </inertia>
        </inertial>
        <collision name='front_left_wheel_collision'>
          <pose>0 0 0 0 0 0</pose>
          <geometry>
            <cylinder>
              <length>0.20000000000000001</length>
              <radius>0.20000000000000001</radius>
            </cylinder>
          </geometry>
        </collision>
        <visual name='front_left_wheel_visual'>
          <pose>0 0 0 0 0 0</pose>
          <geometry>
            <mesh>
              <scale>1 1 1</scale>
              <uri>file:///home/ahmad/ros2_ign_diffdrive/src/ros2_ign_p2p_controllers/model/wheel.dae</uri>
            </mesh>
          </geometry>
          <material>
            <diffuse>0 0 0 1</diffuse>
            <ambient>0 0 0 1</ambient>
          </material>
        </visual>
      </link>
      <joint name='rear_left_wheel_joint' type='revolute'>
        <pose relative_to='base_link'>-0.7795 -0.3835 0.2 1.57 0 0</pose>
        <parent>base_link</parent>
        <child>wheel_back_left</child>
        <axis>
          <xyz>0 0 1</xyz>
          <limit>
            <lower>-10000000000000000</lower>
            <upper>10000000000000000</upper>
          </limit>
          <dynamics>
            <damping>0.20000000000000001</damping>
            <friction>0</friction>
            <spring_reference>0</spring_reference>
            <spring_stiffness>0</spring_stiffness>
          </dynamics>
        </axis>
      </joint>
      <link name='wheel_back_left'>
        <pose relative_to='rear_left_wheel_joint'>0 0 0 0 0 0</pose>
        <inertial>
          <pose>0 0 0 0 0 0</pose>
          <mass>11.300000000000001</mass>
          <inertia>
            <ixx>0.26000000000000001</ixx>
            <ixy>0</ixy>
            <ixz>0</ixz>
            <iyy>0.26000000000000001</iyy>
            <iyz>0</iyz>
            <izz>0.51000000000000001</izz>
          </inertia>
        </inertial>
        <collision name='wheel_back_left_collision'>
          <pose>0 0 0 0 0 0</pose>
          <geometry>
            <cylinder>
              <length>0.20000000000000001</length>
              <radius>0.20000000000000001</radius>
            </cylinder>
          </geometry>
        </collision>
        <visual name='wheel_back_left_visual'>
          <pose>0 0 0 0 0 0</pose>
          <geometry>
            <mesh>
              <scale>1 1 1</scale>
              <uri>file:///home/ahmad/ros2_ign_diffdrive/src/ros2_ign_p2p_controllers/model/wheel.dae</uri>
            </mesh>
          </geometry>
          <material>
            <diffuse>0 0 0 1</diffuse>
            <ambient>0 0 0 1</ambient>
          </material>
        </visual>
      </link>
      <joint name='rear_right_wheel_joint' type='revolute'>
        <pose relative_to='base_link'>-0.7795 0.3835 0.2 1.57 0 0</pose>
        <parent>base_link</parent>
        <child>wheel_back_right</child>
        <axis>
          <xyz>0 0 1</xyz>
          <limit>
            <lower>-10000000000000000</lower>
            <upper>10000000000000000</upper>
          </limit>
          <dynamics>
            <damping>0.20000000000000001</damping>
            <friction>0</friction>
            <spring_reference>0</spring_reference>
            <spring_stiffness>0</spring_stiffness>
          </dynamics>
        </axis>
      </joint>
      <link name='wheel_back_right'>
        <pose relative_to='rear_right_wheel_joint'>0 0 0 0 0 0</pose>
        <inertial>
          <pose>0 0 0 0 0 0</pose>
          <mass>11.300000000000001</mass>
          <inertia>
            <ixx>0.26000000000000001</ixx>
            <ixy>0</ixy>
            <ixz>0</ixz>
            <iyy>0.26000000000000001</iyy>
            <iyz>0</iyz>
            <izz>0.51000000000000001</izz>
          </inertia>
        </inertial>
        <collision name='wheel_back_right_collision'>
          <pose>0 0 0 0 0 0</pose>
          <geometry>
            <cylinder>
              <length>0.20000000000000001</length>
              <radius>0.20000000000000001</radius>
            </cylinder>
          </geometry>
        </collision>
        <visual name='wheel_back_right_visual'>
          <pose>0 0 0 0 0 0</pose>
          <geometry>
            <mesh>
              <scale>1 1 1</scale>
              <uri>file:///home/ahmad/ros2_ign_diffdrive/src/ros2_ign_p2p_controllers/model/wheel.dae</uri>
            </mesh>
          </geometry>
          <material>
            <diffuse>0 0 0 1</diffuse>
            <ambient>0 0 0 1</ambient>
          </material>
        </visual>
      </link>
      <joint name='right_wheel_steering_joint' type='revolute'>
        <pose relative_to='base_link'>0.65 0.3835 0.2 1.57 0 0</pose>
        <parent>base_link</parent>
        <child>right_wheel_steering</child>
        <axis>
          <xyz>0 1 0</xyz>
          <limit>
            <lower>-1.5700000000000001</lower>
            <upper>1.5700000000000001</upper>
            <effort>1000</effort>
            <velocity>30</velocity>
          </limit>
          <dynamics>
            <damping>0.20000000000000001</damping>
            <friction>0</friction>
            <spring_reference>0</spring_reference>
            <spring_stiffness>0</spring_stiffness>
          </dynamics>
        </axis>
      </joint>
      <link name='right_wheel_steering'>
        <pose relative_to='right_wheel_steering_joint'>0 0 0 0 0 0</pose>
        <inertial>
          <pose>0 0 0 0 0 0</pose>
          <mass>0.10000000000000001</mass>
          <inertia>
            <ixx>0</ixx>
            <ixy>0</ixy>
            <ixz>0</ixz>
            <iyy>0</iyy>
            <iyz>0</iyz>
            <izz>0</izz>
          </inertia>
        </inertial>
      </link>
      <joint name='front_right_wheel_joint' type='revolute'>
        <pose relative_to='right_wheel_steering'>0 0 0 0 0 0</pose>
        <parent>right_wheel_steering</parent>
        <child>front_right_wheel</child>
        <axis>
          <xyz>0 0 1</xyz>
          <limit>
            <lower>-10000000000000000</lower>
            <upper>10000000000000000</upper>
          </limit>
          <dynamics>
            <damping>0.20000000000000001</damping>
            <friction>0</friction>
            <spring_reference>0</spring_reference>
            <spring_stiffness>0</spring_stiffness>
          </dynamics>
        </axis>
      </joint>
      <link name='front_right_wheel'>
        <pose relative_to='front_right_wheel_joint'>0 0 0 0 0 0</pose>
        <inertial>
          <pose>0 0 0 0 0 0</pose>
          <mass>11.300000000000001</mass>
          <inertia>
            <ixx>0.26000000000000001</ixx>
            <ixy>0</ixy>
            <ixz>0</ixz>
            <iyy>0.26000000000000001</iyy>
            <iyz>0</iyz>
            <izz>0.51000000000000001</izz>
          </inertia>
        </inertial>
        <collision name='front_right_wheel_collision'>
          <pose>0 0 0 0 0 0</pose>
          <geometry>
            <cylinder>
              <length>0.20000000000000001</length>
              <radius>0.20000000000000001</radius>
            </cylinder>
          </geometry>
        </collision>
        <visual name='front_right_wheel_visual'>
          <pose>0 0 0 0 0 0</pose>
          <geometry>
            <mesh>
              <scale>1 1 1</scale>
              <uri>file:///home/ahmad/ros2_ign_diffdrive/src/ros2_ign_p2p_controllers/model/wheel.dae</uri>
            </mesh>
          </geometry>
          <material>
            <diffuse>0 0 0 1</diffuse>
            <ambient>0 0 0 1</ambient>
          </material>
        </visual>
      </link>
      <!-- <plugin name='ign_ros2_control::IgnitionROS2ControlPlugin'
      filename='ign_ros2_control-system'>
        <parameters>$(find ros2_ign_p2p_controllers)/config/ros2_controller.yaml</parameters>
      </plugin> -->
      <plugin
        filename="ignition-gazebo-ackermann-steering-system"
        name="ignition::gazebo::systems::AckermannSteering">
        <topic>/ackermann/cmd_vel</topic>
        <left_joint>front_left_wheel_joint</left_joint>
        <left_joint>rear_left_wheel_joint</left_joint>
        <right_joint>front_right_wheel_joint</right_joint>
        <right_joint>rear_right_wheel_joint</right_joint>
        <left_steering_joint>right_wheel_steering_joint</left_steering_joint>
        <right_steering_joint>left_wheel_steering_joint</right_steering_joint>
        <kingpin_width>1.0</kingpin_width>
        <steering_limit>0.5</steering_limit>
        <wheel_base>1.4295</wheel_base>
        <wheel_separation>0.767</wheel_separation>
        <wheel_radius>0.2</wheel_radius>
        <min_velocity>-10</min_velocity>
        <max_velocity>100</max_velocity>
        <min_acceleration>-30</min_acceleration>
        <max_acceleration>30</max_acceleration>
      </plugin>
      <plugin
        filename="ignition-gazebo-joint-controller-system"
        name="ignition::gazebo::systems::JointController">
        <joint_name>fork_joint</joint_name>
        <topic>/fork/cmd_vel</topic>
      </plugin>
      <frame name='base_link_to_chassis' attached_to='base_link'>
        <pose>0 0 0.1 0 -0 0</pose>
      </frame>
      <frame name='chassis' attached_to='base_link_to_chassis' />
    </model>
  </world>
</sdf>