<?xml version="1.0"?>
<robot name="forklift_robot" xmlns:xacro="http://ros.org/wiki/xacro">

  <link name="base_link">
    <origin xyz="-1.0795 -0.5334 0" rpy="0 0 0" />
    <visual>
      <geometry>
        <mesh filename="file:///home/ahmad/ros2_ign_diffdrive/src/mini_task/model/base_link.dae" />
      </geometry>
    </visual>
    <collision>
      <origin xyz="1.0795 0.5334 1.3716" rpy="0 0 0" />
      <geometry>
        <box size="2.159 1.0668 2.7432" />
      </geometry>
    </collision>
    <inertial>
      <mass value="500" />
      <inertia ixx="206" ixy="0" ixz="-23" iyy="389" iyz="0" izz="316" />
    </inertial>
  </link>

  <link name="fork">
    <origin xyz="1.0795 -0.368600 1" rpy="0 0 0" />
    <visual>
      <geometry>
        <mesh filename="file:///home/ahmad/ros2_ign_diffdrive/src/mini_task/model/fork.dae" />
      </geometry>
    </visual>
    <collision>
      <geometry>
        <mesh filename="file:///home/ahmad/ros2_ign_diffdrive/src/mini_task/model/fork.dae" />
      </geometry>
    </collision>
    <inertial>
      <mass value="100" />
      <inertia ixx="0.2" ixy="0" ixz="0" iyy="0.3" iyz="0" izz="0.4" />
    </inertial>
  </link>

  <link name="wheel_back_left">
    <visual>
      <geometry>
        <cylinder radius="0.21" length="0.05" />
      </geometry>
    </visual>
    <collision>
      <geometry>
        <cylinder radius="0.21" length="0.05" />
      </geometry>
    </collision>
    <inertial>
      <mass value="5" />
      <inertia ixx="0.001" ixy="0" ixz="0" iyy="0.0015" iyz="0" izz="0.001" />
    </inertial>
  </link>

  <link name="wheel_back_right">
    <visual>
      <geometry>
        <cylinder radius="0.21" length="0.05" />
      </geometry>
    </visual>
    <collision>
      <geometry>
        <cylinder radius="0.21" length="0.05" />
      </geometry>
    </collision>
    <inertial>
      <mass value="5" />
      <inertia ixx="0.001" ixy="0" ixz="0" iyy="0.0015" iyz="0" izz="0.001" />
    </inertial>
  </link>

  <link name="wheel_front_left">
    <visual>
      <geometry>
        <cylinder radius="0.21" length="0.05" />
      </geometry>
    </visual>
    <collision>
      <geometry>
        <cylinder radius="0.21" length="0.05" />
      </geometry>
    </collision>
    <inertial>
      <mass value="5" />
      <inertia ixx="0.001" ixy="0" ixz="0" iyy="0.0015" iyz="0" izz="0.001" />
    </inertial>
  </link>

  <link name="wheel_front_right">
    <visual>
      <geometry>
        <cylinder radius="0.21" length="0.05" />
      </geometry>
    </visual>
    <collision>
      <origin xyz="0 0 0" rpy="1.5707 0 0" />
      <geometry>
        <cylinder radius="0.21" length="0.05" />
      </geometry>
    </collision>
    <inertial>
      <mass value="5" />
      <inertia ixx="0.001" ixy="0" ixz="0" iyy="0.0015" iyz="0" izz="0.001" />
    </inertial>
  </link>

  <joint name="fork_joint" type="prismatic">
    <origin rpy="0 0 0" xyz="2.159 0.175 0" />
    <parent link="base_link" />
    <child link="fork" />
    <limit
      lower="0"
      upper="2"
      velocity="0.1"
      effort="100"
    />
    <axis xyz="0 0 1" />
    <dynamics damping="0.2" />
  </joint>

  <joint name="rear_left_wheel_joint" type="continuous">
    <origin xyz="0.3 0.9 0.2" rpy="1.57 0 0" />
    <parent link="base_link" />
    <child link="wheel_back_left" />
    <axis xyz="0 0 1" />
    <dynamics damping="0.2" />
  </joint>


  <joint name="rear_right_wheel_joint" type="continuous">
    <origin xyz="0.3 0.1 0.2" rpy="01.57 0 0" />
    <parent link="base_link" />
    <child link="wheel_back_right" />
    <axis xyz="0 0 1" />
    <dynamics damping="0.2" />
  </joint>

  <joint name="left_wheel_steering_joint" type="continuous">
    <origin xyz="1.8 0.9 0.2" rpy="1.57 0 0" />
    <parent link="base_link" />
    <child link="wheel_front_left" />
    <axis xyz="0 1 0" />
    <dynamics damping="0.2" />
  </joint>

  <joint name="right_wheel_steering_joint" type="continuous">
    <origin xyz="01.8 0.1 0.2" rpy="1.57 0 0" />
    <parent link="base_link" />
    <child link="wheel_front_right" />
    <axis xyz="0 1 0" />
    <dynamics damping="0.2" />
  </joint>

  <ros2_control name="IgnitionSystem" type="system">
    <hardware>
      <plugin>ign_ros2_control/IgnitionSystem</plugin>
    </hardware>
    <joint name="rear_left_wheel_joint">
      <command_interface name="velocity" />
      <state_interface name="velocity" />
      <state_interface name="position" />
    </joint>
    <joint name="rear_right_wheel_joint">
      <command_interface name="velocity" />
      <state_interface name="velocity" />
      <state_interface name="position" />
    </joint>
    <joint name="left_wheel_steering_joint">
      <command_interface name="position" />
      <state_interface name="position" />
    </joint>
    <joint name="right_wheel_steering_joint">
      <command_interface name="position" />
      <state_interface name="position" />
    </joint>
    <joint name="fork_joint">
      <command_interface name="position">
        <param name="min">0</param>
        <param name="max">2</param>
      </command_interface>
      <state_interface name="position">
        <param name="initial_value">0</param>
      </state_interface>
      <state_interface name="velocity" />
      <state_interface name="effort" />
    </joint>
  </ros2_control>

  <gazebo>
    <plugin filename="ign_ros2_control-system" name="ign_ros2_control::IgnitionROS2ControlPlugin">
      <parameters>$(find mini_task)/config/ros2_controller.yaml</parameters>
    </plugin>
  </gazebo>


</robot>